Workbook

Sheet Parameters
A1: Probability | B1: 0.7
A2: Mean | B2: 40
A3: StdDev | B3: 10

Sheet Data
A1: Data | B1: Groups
A2: =ROUND(_xlfn.NORM.INV(RAND(),Parameters!$B$2,Parameters!$B$3),0) -> 32 | B2: =RANDBETWEEN(1,4) -> 2
A3: =ROUND(_xlfn.NORM.INV(RAND(),Parameters!$B$2,Parameters!$B$3),0) -> 27 | B3: =RANDBETWEEN(1,4) -> 4
A4: =ROUND(_xlfn.NORM.INV(RAND(),Parameters!$B$2,Parameters!$B$3),0) -> 43 | B4: =RANDBETWEEN(1,4) -> 2
A5: =ROUND(_xlfn.NORM.INV(RAND(),Parameters!$B$2,Parameters!$B$3),0) -> 44 | B5: =RANDBETWEEN(1,4) -> 1
A6: =ROUND(_xlfn.NORM.INV(RAND(),Parameters!$B$2,Parameters!$B$3),0) -> 38 | B6: =RANDBETWEEN(1,4) -> 4
A7: =ROUND(_xlfn.NORM.INV(RAND(),Parameters!$B$2,Parameters!$B$3),0) -> 37 | B7: =RANDBETWEEN(1,4) -> 2
A8: =ROUND(_xlfn.NORM.INV(RAND(),Parameters!$B$2,Parameters!$B$3),0) -> 19 | B8: =RANDBETWEEN(1,4) -> 1
A9: =ROUND(_xlfn.NORM.INV(RAND(),Parameters!$B$2,Parameters!$B$3),0) -> 52 | B9: =RANDBETWEEN(1,4) -> 1
A10: =ROUND(_xlfn.NORM.INV(RAND(),Parameters!$B$2,Parameters!$B$3),0) -> 39 | B10: =RANDBETWEEN(1,4) -> 2
A11: =ROUND(_xlfn.NORM.INV(RAND(),Parameters!$B$2,Parameters!$B$3),0) -> 39 | B11: =RANDBETWEEN(1,4) -> 1
A12: =ROUND(_xlfn.NORM.INV(RAND(),Parameters!$B$2,Parameters!$B$3),0) -> 42 | B12: =RANDBETWEEN(1,4) -> 1
A13: =ROUND(_xlfn.NORM.INV(RAND(),Parameters!$B$2,Parameters!$B$3),0) -> 55 | B13: =RANDBETWEEN(1,4) -> 2
... A251: =ROUND(_xlfn.NORM.INV(RAND(),Parameters!$B$2,Parameters!$B$3),0) -> 40 | B251: =RANDBETWEEN(1,4) -> 2

Sheet Sample
A1: Data | B1: Groups | C1: Sample data
A2: 35 | B2: 2 | C2: =IF(B2=2,A2," ") -> 35
A3: 46 | B3: 1 | C3: =IF(B3=2,A3," ")
A4: 43 | B4: 1 | C4: =IF(B4=2,A4," ")
A5: 15 | B5: 2 | C5: =IF(B5=2,A5," ") -> 15
A6: 22 | B6: 1 | C6: =IF(B6=2,A6," ")
A7: 46 | B7: 1 | C7: =IF(B7=2,A7," ")
A8: 39 | B8: 1 | C8: =IF(B8=2,A8," ")
A9: 36 | B9: 3 | C9: =IF(B9=2,A9," ")
A10: 48 | B10: 4 | C10: =IF(B10=2,A10," ")
A11: 38 | B11: 3 | C11: =IF(B11=2,A11," ")
A12: 40 | B12: 2 | C12: =IF(B12=2,A12," ") -> 40
A13: 50 | B13: 2 | C13: =IF(B13=2,A13," ") -> 50
... A251: 36 | B251: 1 | C251: =IF(B251=2,A251," ")

Sheet Statistical insight
A1: STDDEV | B1: =SQRT(B10) -> 10.447881
A2: EXPECTED VALUE | B2: =AVERAGE(Sample!C2:C251) -> 37.405797
A3: COUNT | B3: =COUNT(Sample!C2:C251) -> 69
A4: CONFIDENCE RATE | B4: 0.95
A5: Estimation of p parameter | B5: =_xlfn.NORM.S.INV(0.975) -> 1.959964
A6: Confidence interval (lower limit) | B6: =B2-B5*B11 -> 34.940599
A7: Confidence interval (upper limit) | B7: =B2+B5*B11 -> 39.870995
A10: varianza p | B10: =_xlfn.VAR.P(Sample!A2:A251) -> 109.15822
A11: standar error p | B11: =B1/SQRT(B3) -> 1.2577771

Sheet (Un)correlated variables
A1: Sample data | B1: Number of cats | C1: Age of partner
A2: 35 | B2: 4 | C2: =ROUND($H$3*A2+SQRT(1-$E$3)*B2,0) -> 35 | E2: r^2 | G2: Correlation age and cats | H2: =PEARSON(A2:A70,B2:B70) -> -0.083986936 | I2: Correlazione negativa, all'aumentare di una variabile, l'altra diminuisce
A3: 15 | B3: 6 | C3: =ROUND($H$3*A3+SQRT(1-$E$3)*B3,0) -> 16 | E3: =H3^2 -> 0.9409 | G3: Desired correlation( r ) | H3: 0.97
A4: 40 | B4: 2 | C4: =ROUND($H$3*A4+SQRT(1-$E$3)*B4,0) -> 39 | G4: Actual correlation(r') | H4: =PEARSON(A2:A70,C2:C70) -> 0.99878042 | I4: Correlazione positiva, all'aumentare di una variabile, l'altra aumenta
A5: 50 | B5: 3 | C5: =ROUND($H$3*A5+SQRT(1-$E$3)*B5,0) -> 49
A6: 30 | B6: 7 | C6: =ROUND($H$3*A6+SQRT(1-$E$3)*B6,0) -> 31
A7: 52 | B7: 3 | C7: =ROUND($H$3*A7+SQRT(1-$E$3)*B7,0) -> 51
A8: 32 | B8: 3 | C8: =ROUND($H$3*A8+SQRT(1-$E$3)*B8,0) -> 32
A9: 40 | B9: 5 | C9: =ROUND($H$3*A9+SQRT(1-$E$3)*B9,0) -> 40
A10: 15 | B10: 2 | C10: =ROUND($H$3*A10+SQRT(1-$E$3)*B10,0) -> 15
A11: 32 | B11: 2 | C11: =ROUND($H$3*A11+SQRT(1-$E$3)*B11,0) -> 32
A12: 31 | B12: 2 | C12: =ROUND($H$3*A12+SQRT(1-$E$3)*B12,0) -> 31
A13: 18 | B13: 5 | C13: =ROUND($H$3*A13+SQRT(1-$E$3)*B13,0) -> 19
A14: 29 | B14: 5 | C14: =ROUND($H$3*A14+SQRT(1-$E$3)*B14,0) -> 29
A15: 58 | B15: 5 | C15: =ROUND($H$3*A15+SQRT(1-$E$3)*B15,0) -> 57
A16: 36 | B16: 7 | C16: =ROUND($H$3*A16+SQRT(1-$E$3)*B16,0) -> 37
... A70: 39 | B70: 6 | C70: =ROUND($H$3*A70+SQRT(1-$E$3)*B70,0) -> 39

Sheet Linear regression
A1: Y (age) | B1: X (rank)
A2: ='(Un)correlated variables'!A47 -> 14 | B2: 1
A3: ='(Un)correlated variables'!A3 -> 15 | B3: =B2+1 -> 2
A4: ='(Un)correlated variables'!A10 -> 15 | B4: =B3+1 -> 3
A5: ='(Un)correlated variables'!C10 -> 15 | B5: =B4+1 -> 4
A6: ='(Un)correlated variables'!C47 -> 15 | B6: =B5+1 -> 5
A7: ='(Un)correlated variables'!A18 -> 16 | B7: =B6+1 -> 6
A8: ='(Un)correlated variables'!C3 -> 16 | B8: =B7+1 -> 7
A9: ='(Un)correlated variables'!C18 -> 16 | B9: =B8+1 -> 8
A10: ='(Un)correlated variables'!A13 -> 18 | B10: =B9+1 -> 9 | E10: =_xlfn.FORECAST.LINEAR(160,A2:A139,B2:B139) -> 61.881693
A11: ='(Un)correlated variables'!C13 -> 19 | B11: =B10+1 -> 10
A12: ='(Un)correlated variables'!A31 -> 20 | B12: =B11+1 -> 11
A13: ='(Un)correlated variables'!A45 -> 20 | B13: =B12+1 -> 12
A14: ='(Un)correlated variables'!C31 -> 21 | B14: =B13+1 -> 13
A15: ='(Un)correlated variables'!C45 -> 21 | B15: =B14+1 -> 14
A16: ='(Un)correlated variables'!A46 -> 25 | B16: =B15+1 -> 15
A17: ='(Un)correlated variables'!C46 -> 25 | B17: =B16+1 -> 16
A18: ='(Un)correlated variables'!C26 -> 26 | B18: =B17+1 -> 17
A19: ='(Un)correlated variables'!A26 -> 27 | B19: =B18+1 -> 18
A20: ='(Un)correlated variables'!A58 -> 27 | B20: =B19+1 -> 19
A21: ='(Un)correlated variables'!A68 -> 27 | B21: =B20+1 -> 20
A22: ='(Un)correlated variables'!C58 -> 27 | B22: =B21+1 -> 21
A23: ='(Un)correlated variables'!A20 -> 28 | B23: =B22+1 -> 22
A24: ='(Un)correlated variables'!C20 -> 28 | B24: =B23+1 -> 23
A25: ='(Un)correlated variables'!C41 -> 28 | B25: =B24+1 -> 24
A26: ='(Un)correlated variables'!C68 -> 28 | B26: =B25+1 -> 25
A27: ='(Un)correlated variables'!A14 -> 29 | B27: =B26+1 -> 26
A28: ='(Un)correlated variables'!A36 -> 29 | B28: =B27+1 -> 27
A29: ='(Un)correlated variables'!A41 -> 29 | B29: =B28+1 -> 28
A30: ='(Un)correlated variables'!C14 -> 29 | B30: =B29+1 -> 29
A31: ='(Un)correlated variables'!C36 -> 29 | B31: =B30+1 -> 30
A32: ='(Un)correlated variables'!A6 -> 30 | B32: =B31+1 -> 31
A33: ='(Un)correlated variables'!C62 -> 30 | B33: =B32+1 -> 32
A34: ='(Un)correlated variables'!A12 -> 31 | B34: =B33+1 -> 33
A35: ='(Un)correlated variables'!A17 -> 31 | B35: =B34+1 -> 34
A36: ='(Un)correlated variables'!A50 -> 31 | B36: =B35+1 -> 35
A37: ='(Un)correlated variables'!A62 -> 31 | B37: =B36+1 -> 36
A38: ='(Un)correlated variables'!C6 -> 31 | B38: =B37+1 -> 37
A39: ='(Un)correlated variables'!C12 -> 31 | B39: =B38+1 -> 38
A40: ='(Un)correlated variables'!C50 -> 31 | B40: =B39+1 -> 39
...
